[2019-04-03 11:08:06,254] [base.py:256] [base:handle_uncaught_exception] [ERROR]- Internal Server Error: /case
Traceback (most recent call last):
  File "C:\anaconda3\envs\kktest\lib\site-packages\django\core\handlers\base.py", line 151, in get_response
    % (callback.__module__, view_name))
ValueError: The view outeruser.views.case didn't return an HttpResponse object. It returned None instead.
[2019-04-03 11:09:23,997] [base.py:170] [base:get_response] [WARNING]- Not Found: /base
[2019-04-03 12:52:53,835] [base.py:256] [base:handle_uncaught_exception] [ERROR]- Internal Server Error: /addCase
Traceback (most recent call last):
  File "C:\anaconda3\envs\kktest\lib\site-packages\django\core\handlers\base.py", line 132, in get_response
    response = wrapped_callback(request, *callback_args, **callback_kwargs)
  File "C:\Users\djcps\Desktop\我的django\kkTest\outeruser\views.py", line 530, in add_case
    dic = json.loads(request)
  File "C:\anaconda3\envs\kktest\lib\json\__init__.py", line 348, in loads
    'not {!r}'.format(s.__class__.__name__))
TypeError: the JSON object must be str, bytes or bytearray, not 'WSGIRequest'
[2019-04-03 12:55:21,815] [base.py:256] [base:handle_uncaught_exception] [ERROR]- Internal Server Error: /addCase
Traceback (most recent call last):
  File "C:\anaconda3\envs\kktest\lib\site-packages\django\core\urlresolvers.py", line 394, in urlconf_module
    return self._urlconf_module
AttributeError: 'RegexURLResolver' object has no attribute '_urlconf_module'

During handling of the above exception, another exception occurred:

Traceback (most recent call last):
  File "C:\anaconda3\envs\kktest\lib\site-packages\django\core\handlers\base.py", line 108, in get_response
    response = middleware_method(request)
  File "C:\anaconda3\envs\kktest\lib\site-packages\django\middleware\common.py", line 74, in process_request
    if (not urlresolvers.is_valid_path(request.path_info, urlconf) and
  File "C:\anaconda3\envs\kktest\lib\site-packages\django\core\urlresolvers.py", line 647, in is_valid_path
    resolve(path, urlconf)
  File "C:\anaconda3\envs\kktest\lib\site-packages\django\core\urlresolvers.py", line 522, in resolve
    return get_resolver(urlconf).resolve(path)
  File "C:\anaconda3\envs\kktest\lib\site-packages\django\core\urlresolvers.py", line 366, in resolve
    for pattern in self.url_patterns:
  File "C:\anaconda3\envs\kktest\lib\site-packages\django\core\urlresolvers.py", line 402, in url_patterns
    patterns = getattr(self.urlconf_module, "urlpatterns", self.urlconf_module)
  File "C:\anaconda3\envs\kktest\lib\site-packages\django\core\urlresolvers.py", line 396, in urlconf_module
    self._urlconf_module = import_module(self.urlconf_name)
  File "C:\anaconda3\envs\kktest\lib\importlib\__init__.py", line 126, in import_module
    return _bootstrap._gcd_import(name[level:], package, level)
  File "<frozen importlib._bootstrap>", line 978, in _gcd_import
  File "<frozen importlib._bootstrap>", line 961, in _find_and_load
  File "<frozen importlib._bootstrap>", line 950, in _find_and_load_unlocked
  File "<frozen importlib._bootstrap>", line 655, in _load_unlocked
  File "<frozen importlib._bootstrap_external>", line 678, in exec_module
  File "<frozen importlib._bootstrap>", line 205, in _call_with_frames_removed
  File "C:\Users\djcps\Desktop\我的django\kkTest\kkTest\urls.py", line 18, in <module>
    import outeruser.urls
  File "C:\Users\djcps\Desktop\我的django\kkTest\outeruser\urls.py", line 2, in <module>
    from outeruser import views
  File "C:\Users\djcps\Desktop\我的django\kkTest\outeruser\views.py", line 541
    api = {"url":url,"name":name,""method":method,"headers":headers,"body":body,"params":params,"assertion":
                                        ^
SyntaxError: invalid syntax
[2019-04-03 12:56:21,983] [base.py:256] [base:handle_uncaught_exception] [ERROR]- Internal Server Error: /addCase
Traceback (most recent call last):
  File "C:\anaconda3\envs\kktest\lib\site-packages\django\core\handlers\base.py", line 132, in get_response
    response = wrapped_callback(request, *callback_args, **callback_kwargs)
  File "C:\Users\djcps\Desktop\我的django\kkTest\outeruser\views.py", line 530, in add_case
    dic = json.loads(request)
  File "C:\anaconda3\envs\kktest\lib\json\__init__.py", line 348, in loads
    'not {!r}'.format(s.__class__.__name__))
TypeError: the JSON object must be str, bytes or bytearray, not 'WSGIRequest'
[2019-04-03 13:00:30,401] [base.py:256] [base:handle_uncaught_exception] [ERROR]- Internal Server Error: /addCase
Traceback (most recent call last):
  File "C:\anaconda3\envs\kktest\lib\site-packages\django\core\handlers\base.py", line 132, in get_response
    response = wrapped_callback(request, *callback_args, **callback_kwargs)
  File "C:\Users\djcps\Desktop\我的django\kkTest\outeruser\views.py", line 543, in add_case
    Api.objects.create(**api)
  File "C:\anaconda3\envs\kktest\lib\site-packages\django\db\models\manager.py", line 127, in manager_method
    return getattr(self.get_queryset(), name)(*args, **kwargs)
  File "C:\anaconda3\envs\kktest\lib\site-packages\django\db\models\query.py", line 346, in create
    obj = self.model(**kwargs)
  File "C:\anaconda3\envs\kktest\lib\site-packages\django\db\models\base.py", line 480, in __init__
    raise TypeError("'%s' is an invalid keyword argument for this function" % list(kwargs)[0])
TypeError: 'headers' is an invalid keyword argument for this function
[2019-04-03 13:02:36,519] [base.py:256] [base:handle_uncaught_exception] [ERROR]- Internal Server Error: /addCase
Traceback (most recent call last):
  File "C:\anaconda3\envs\kktest\lib\site-packages\django\core\handlers\base.py", line 132, in get_response
    response = wrapped_callback(request, *callback_args, **callback_kwargs)
  File "C:\Users\djcps\Desktop\我的django\kkTest\outeruser\views.py", line 543, in add_case
    Api.objects.create(**api)
  File "C:\anaconda3\envs\kktest\lib\site-packages\django\db\models\manager.py", line 127, in manager_method
    return getattr(self.get_queryset(), name)(*args, **kwargs)
  File "C:\anaconda3\envs\kktest\lib\site-packages\django\db\models\query.py", line 346, in create
    obj = self.model(**kwargs)
  File "C:\anaconda3\envs\kktest\lib\site-packages\django\db\models\base.py", line 480, in __init__
    raise TypeError("'%s' is an invalid keyword argument for this function" % list(kwargs)[0])
TypeError: 'headers' is an invalid keyword argument for this function
[2019-04-03 13:04:03,529] [base.py:256] [base:handle_uncaught_exception] [ERROR]- Internal Server Error: /addCase
Traceback (most recent call last):
  File "C:\anaconda3\envs\kktest\lib\site-packages\django\core\handlers\base.py", line 132, in get_response
    response = wrapped_callback(request, *callback_args, **callback_kwargs)
  File "C:\Users\djcps\Desktop\我的django\kkTest\outeruser\views.py", line 543, in add_case
    Api.objects.create(**api)
  File "C:\anaconda3\envs\kktest\lib\site-packages\django\db\models\manager.py", line 127, in manager_method
    return getattr(self.get_queryset(), name)(*args, **kwargs)
  File "C:\anaconda3\envs\kktest\lib\site-packages\django\db\models\query.py", line 346, in create
    obj = self.model(**kwargs)
  File "C:\anaconda3\envs\kktest\lib\site-packages\django\db\models\base.py", line 480, in __init__
    raise TypeError("'%s' is an invalid keyword argument for this function" % list(kwargs)[0])
TypeError: 'headers' is an invalid keyword argument for this function
[2019-04-03 13:09:25,077] [base.py:256] [base:handle_uncaught_exception] [ERROR]- Internal Server Error: /addCase
Traceback (most recent call last):
  File "C:\anaconda3\envs\kktest\lib\site-packages\django\core\handlers\base.py", line 132, in get_response
    response = wrapped_callback(request, *callback_args, **callback_kwargs)
  File "C:\Users\djcps\Desktop\我的django\kkTest\outeruser\views.py", line 543, in add_case
    Case.objects.create(**api)
TypeError: create() argument after ** must be a mapping, not function
[2019-04-03 13:10:39,626] [base.py:256] [base:handle_uncaught_exception] [ERROR]- Internal Server Error: /addCase
Traceback (most recent call last):
  File "C:\anaconda3\envs\kktest\lib\site-packages\django\db\backends\utils.py", line 64, in execute
    return self.cursor.execute(sql, params)
  File "C:\anaconda3\envs\kktest\lib\site-packages\django\db\backends\mysql\base.py", line 124, in execute
    return self.cursor.execute(query, args)
  File "C:\anaconda3\envs\kktest\lib\site-packages\pymysql\cursors.py", line 170, in execute
    result = self._query(query)
  File "C:\anaconda3\envs\kktest\lib\site-packages\pymysql\cursors.py", line 328, in _query
    conn.query(q)
  File "C:\anaconda3\envs\kktest\lib\site-packages\pymysql\connections.py", line 517, in query
    self._affected_rows = self._read_query_result(unbuffered=unbuffered)
  File "C:\anaconda3\envs\kktest\lib\site-packages\pymysql\connections.py", line 732, in _read_query_result
    result.read()
  File "C:\anaconda3\envs\kktest\lib\site-packages\pymysql\connections.py", line 1075, in read
    first_packet = self.connection._read_packet()
  File "C:\anaconda3\envs\kktest\lib\site-packages\pymysql\connections.py", line 684, in _read_packet
    packet.check_error()
  File "C:\anaconda3\envs\kktest\lib\site-packages\pymysql\protocol.py", line 220, in check_error
    err.raise_mysql_exception(self._data)
  File "C:\anaconda3\envs\kktest\lib\site-packages\pymysql\err.py", line 109, in raise_mysql_exception
    raise errorclass(errno, errval)
pymysql.err.IntegrityError: (1452, 'Cannot add or update a child row: a foreign key constraint fails (`kktest`.`t_case`, CONSTRAINT `t_case_api_id_28c065b4d3dbdfaa_fk_t_api_apiid` FOREIGN KEY (`api_id`) REFERENCES `t_api` (`apiid`))')

The above exception was the direct cause of the following exception:

Traceback (most recent call last):
  File "C:\anaconda3\envs\kktest\lib\site-packages\django\core\handlers\base.py", line 132, in get_response
    response = wrapped_callback(request, *callback_args, **callback_kwargs)
  File "C:\Users\djcps\Desktop\我的django\kkTest\outeruser\views.py", line 543, in add_case
    Case.objects.create(**case)
  File "C:\anaconda3\envs\kktest\lib\site-packages\django\db\models\manager.py", line 127, in manager_method
    return getattr(self.get_queryset(), name)(*args, **kwargs)
  File "C:\anaconda3\envs\kktest\lib\site-packages\django\db\models\query.py", line 348, in create
    obj.save(force_insert=True, using=self.db)
  File "C:\anaconda3\envs\kktest\lib\site-packages\django\db\models\base.py", line 710, in save
    force_update=force_update, update_fields=update_fields)
  File "C:\anaconda3\envs\kktest\lib\site-packages\django\db\models\base.py", line 738, in save_base
    updated = self._save_table(raw, cls, force_insert, force_update, using, update_fields)
  File "C:\anaconda3\envs\kktest\lib\site-packages\django\db\models\base.py", line 822, in _save_table
    result = self._do_insert(cls._base_manager, using, fields, update_pk, raw)
  File "C:\anaconda3\envs\kktest\lib\site-packages\django\db\models\base.py", line 861, in _do_insert
    using=using, raw=raw)
  File "C:\anaconda3\envs\kktest\lib\site-packages\django\db\models\manager.py", line 127, in manager_method
    return getattr(self.get_queryset(), name)(*args, **kwargs)
  File "C:\anaconda3\envs\kktest\lib\site-packages\django\db\models\query.py", line 920, in _insert
    return query.get_compiler(using=using).execute_sql(return_id)
  File "C:\anaconda3\envs\kktest\lib\site-packages\django\db\models\sql\compiler.py", line 974, in execute_sql
    cursor.execute(sql, params)
  File "C:\anaconda3\envs\kktest\lib\site-packages\django\db\backends\utils.py", line 79, in execute
    return super(CursorDebugWrapper, self).execute(sql, params)
  File "C:\anaconda3\envs\kktest\lib\site-packages\django\db\backends\utils.py", line 64, in execute
    return self.cursor.execute(sql, params)
  File "C:\anaconda3\envs\kktest\lib\site-packages\django\db\utils.py", line 97, in __exit__
    six.reraise(dj_exc_type, dj_exc_value, traceback)
  File "C:\anaconda3\envs\kktest\lib\site-packages\django\utils\six.py", line 658, in reraise
    raise value.with_traceback(tb)
  File "C:\anaconda3\envs\kktest\lib\site-packages\django\db\backends\utils.py", line 64, in execute
    return self.cursor.execute(sql, params)
  File "C:\anaconda3\envs\kktest\lib\site-packages\django\db\backends\mysql\base.py", line 124, in execute
    return self.cursor.execute(query, args)
  File "C:\anaconda3\envs\kktest\lib\site-packages\pymysql\cursors.py", line 170, in execute
    result = self._query(query)
  File "C:\anaconda3\envs\kktest\lib\site-packages\pymysql\cursors.py", line 328, in _query
    conn.query(q)
  File "C:\anaconda3\envs\kktest\lib\site-packages\pymysql\connections.py", line 517, in query
    self._affected_rows = self._read_query_result(unbuffered=unbuffered)
  File "C:\anaconda3\envs\kktest\lib\site-packages\pymysql\connections.py", line 732, in _read_query_result
    result.read()
  File "C:\anaconda3\envs\kktest\lib\site-packages\pymysql\connections.py", line 1075, in read
    first_packet = self.connection._read_packet()
  File "C:\anaconda3\envs\kktest\lib\site-packages\pymysql\connections.py", line 684, in _read_packet
    packet.check_error()
  File "C:\anaconda3\envs\kktest\lib\site-packages\pymysql\protocol.py", line 220, in check_error
    err.raise_mysql_exception(self._data)
  File "C:\anaconda3\envs\kktest\lib\site-packages\pymysql\err.py", line 109, in raise_mysql_exception
    raise errorclass(errno, errval)
django.db.utils.IntegrityError: (1452, 'Cannot add or update a child row: a foreign key constraint fails (`kktest`.`t_case`, CONSTRAINT `t_case_api_id_28c065b4d3dbdfaa_fk_t_api_apiid` FOREIGN KEY (`api_id`) REFERENCES `t_api` (`apiid`))')
